<?xml version="1.0" ?>
<mujoco model="ur5e_pick_place">
    <compiler angle="radian" meshdir="assets" autolimits="true"/>

    <option integrator="implicitfast" gravity="0 0 -9.81">
        <flag contact="enable"/>
    </option>

    <!-- Default settings for physics and contact -->
    <default>
        <geom friction="1 0.005 0.0001" condim="3"/>
        <default class="ur5e">
            <material specular="0.5" shininess="0.25"/>
            <joint axis="0 1 0" range="-6.28319 6.28319" armature="0.1"/>
            <general gaintype="fixed" biastype="affine" ctrlrange="-6.2831 6.2831" gainprm="2000" biasprm="0 -2000 -400"
                forcerange="-150 150"/>
            <default class="size3">
                <default class="size3_limited">
                <joint range="-3.1415 3.1415"/>
                <general ctrlrange="-3.1415 3.1415"/>
                </default>
            </default>
            <default class="size1">
                <general gainprm="500" biasprm="0 -500 -100" forcerange="-28 28"/>
            </default>
            <default class="visual">
                <geom type="mesh" contype="0" conaffinity="0" group="2"/>
            </default>
            <default class="collision">
                <geom type="capsule" group="3"/>
                <default class="eef_collision">
                <geom type="cylinder"/>
                </default>
            </default>
            <site size="0.001" rgba="0.5 0.5 0.5 0.3" group="4"/>
        </default>
    </default>

    <!-- Define materials -->
    <asset>
        <material class="ur5e" name="black" rgba="0.033 0.033 0.033 1"/>
        <material class="ur5e" name="jointgray" rgba="0.278 0.278 0.278 1"/>
        <material class="ur5e" name="linkgray" rgba="0.82 0.82 0.82 1"/>
        <material class="ur5e" name="urblue" rgba="0.49 0.678 0.8 1"/>

        <mesh file="base_0.obj"/>
        <mesh file="base_1.obj"/>
        <mesh file="shoulder_0.obj"/>
        <mesh file="shoulder_1.obj"/>
        <mesh file="shoulder_2.obj"/>
        <mesh file="upperarm_0.obj"/>
        <mesh file="upperarm_1.obj"/>
        <mesh file="upperarm_2.obj"/>
        <mesh file="upperarm_3.obj"/>
        <mesh file="forearm_0.obj"/>
        <mesh file="forearm_1.obj"/>
        <mesh file="forearm_2.obj"/>
        <mesh file="forearm_3.obj"/>
        <mesh file="wrist1_0.obj"/>
        <mesh file="wrist1_1.obj"/>
        <mesh file="wrist1_2.obj"/>
        <mesh file="wrist2_0.obj"/>
        <mesh file="wrist2_1.obj"/>
        <mesh file="wrist2_2.obj"/>
        <mesh file="wrist3.obj"/>

        <material name="blue" rgba="0.49 0.678 0.8 1"/>
        <material name="gray" rgba="0.82 0.82 0.82 1"/>
        <material name="bin1_color" rgba="0.2 0.3 0.7 0.8"/>
        <material name="bin2_color" rgba="0.7 0.3 0.2 0.8"/>
        <material name="cube_color" rgba="0.1 0.8 0.1 1"/>
        <material name="floor_color" rgba="0.9 0.9 0.9 1"/>
        <material name="eef_color" rgba="0.7 0.7 0.7 1"/>

        <mesh name="wedge" file="wedged_panel.stl"/>
    </asset>

    <worldbody>
        <!-- Floor -->
        <geom name="floor" type="plane" size="2 2 0.1" material="floor_color"/>
        
        <!-- Lighting -->
        <light name="spotlight" pos="0 0 3" dir="0 0 -1" diffuse="0.5 0.5 0.5"/>
        <light name="ambient" pos="0 0 4" dir="0 0 -1" diffuse="0.2 0.2 0.2"/>
        
        <!-- UR5e Robot -->
        <body name="base" quat="1 0 0 1" childclass="ur5e">
        <inertial mass="4.0" pos="0 0 0" diaginertia="0.00443333156 0.00443333156 0.0072"/>
        <geom mesh="base_0" material="black" class="visual"/>
        <geom mesh="base_1" material="jointgray" class="visual"/>
        <body name="shoulder_link" pos="0 0 0.163">
            <inertial mass="3.7" pos="0 0 0" diaginertia="0.0102675 0.0102675 0.00666"/>
            <joint name="shoulder_pan_joint" class="size3" axis="0 0 1"/>
            <geom mesh="shoulder_0" material="urblue" class="visual"/>
            <geom mesh="shoulder_1" material="black" class="visual"/>
            <geom mesh="shoulder_2" material="jointgray" class="visual"/>
            <geom class="collision" size="0.06 0.06" pos="0 0 -0.04"/>
            <body name="upper_arm_link" pos="0 0.138 0" quat="1 0 1 0">
            <inertial mass="8.393" pos="0 0 0.2125" diaginertia="0.133886 0.133886 0.0151074"/>
            <joint name="shoulder_lift_joint" class="size3"/>
            <geom mesh="upperarm_0" material="linkgray" class="visual"/>
            <geom mesh="upperarm_1" material="black" class="visual"/>
            <geom mesh="upperarm_2" material="jointgray" class="visual"/>
            <geom mesh="upperarm_3" material="urblue" class="visual"/>
            <geom class="collision" pos="0 -0.04 0" quat="1 1 0 0" size="0.06 0.06"/>
            <geom class="collision" size="0.05 0.2" pos="0 0 0.2"/>
            <body name="forearm_link" pos="0 -0.131 0.425">
                <inertial mass="2.275" pos="0 0 0.196" diaginertia="0.0311796 0.0311796 0.004095"/>
                <joint name="elbow_joint" class="size3_limited"/>
                <geom mesh="forearm_0" material="urblue" class="visual"/>
                <geom mesh="forearm_1" material="linkgray" class="visual"/>
                <geom mesh="forearm_2" material="black" class="visual"/>
                <geom mesh="forearm_3" material="jointgray" class="visual"/>
                <geom class="collision" pos="0 0.08 0" quat="1 1 0 0" size="0.055 0.06"/>
                <geom class="collision" size="0.038 0.19" pos="0 0 0.2"/>
                <body name="wrist_1_link" pos="0 0 0.392" quat="1 0 1 0">
                <inertial mass="1.219" pos="0 0.127 0" diaginertia="0.0025599 0.0025599 0.0021942"/>
                <joint name="wrist_1_joint" class="size1"/>
                <geom mesh="wrist1_0" material="black" class="visual"/>
                <geom mesh="wrist1_1" material="urblue" class="visual"/>
                <geom mesh="wrist1_2" material="jointgray" class="visual"/>
                <geom class="collision" pos="0 0.05 0" quat="1 1 0 0" size="0.04 0.07"/>
                <body name="wrist_2_link" pos="0 0.127 0">
                    <inertial mass="1.219" pos="0 0 0.1" diaginertia="0.0025599 0.0025599 0.0021942"/>
                    <joint name="wrist_2_joint" axis="0 0 1" class="size1"/>
                    <geom mesh="wrist2_0" material="black" class="visual"/>
                    <geom mesh="wrist2_1" material="urblue" class="visual"/>
                    <geom mesh="wrist2_2" material="jointgray" class="visual"/>
                    <geom class="collision" size="0.04 0.06" pos="0 0 0.04"/>
                    <geom class="collision" pos="0 0.02 0.1" quat="1 1 0 0" size="0.04 0.04"/>
                    <body name="wrist_3_link" pos="0 0 0.1">
                    <inertial mass="0.1889" pos="0 0.0771683 0" quat="1 0 0 1"
                        diaginertia="0.000132134 9.90863e-05 9.90863e-05"/>
                    <joint name="wrist_3_joint" class="size1"/>
                    <geom material="linkgray" mesh="wrist3" class="visual"/>
                    <geom class="eef_collision" pos="0 0.08 0" quat="1 1 0 0" size="0.04 0.02"/>
                    <site name="attachment_site" pos="0 0.1 0" quat="-1 1 0 0"/>
                        <geom name="wedge" type="mesh" mesh="wedge" rgba="0.8 0.2 0.2 1" pos="-0.045 0.187 0" quat="0 1 1 0"/>
                    </body>
                </body>
                </body>
            </body>
            </body>
        </body>
        </body>


        <!-- Bin 1 -->
        <body name="bin1" pos="0.6 0.4 0.5">
            <geom name="bin1_bottom" type="box" size="0.15 0.15 0.01" material="bin1_color"
                mass="1"/>
            <geom name="bin1_side1" type="box" size="0.15 0.01 0.1" pos="0 0.15 0.1" material="bin1_color"/>
            <geom name="bin1_side2" type="box" size="0.15 0.01 0.1" pos="0 -0.15 0.1" material="bin1_color"/>
            <geom name="bin1_side3" type="box" size="0.01 0.15 0.1" pos="0.15 0 0.1" material="bin1_color"/>
            <!-- <geom name="bin1_side4" type="box" size="0.01 0.15 0.1" pos="-0.15 0 0.1" material="bin1_color"/> -->
        </body>

        <!-- Bin 2 -->
        <body name="bin2" pos="-0.6 0.4 0.5">
            <geom name="bin2_bottom" type="box" size="0.15 0.15 0.01" material="bin2_color"
                mass="1"/>
            <geom name="bin2_side1" type="box" size="0.15 0.01 0.1" pos="0 0.15 0.1" material="bin2_color"/>
            <geom name="bin2_side2" type="box" size="0.15 0.01 0.1" pos="0 -0.15 0.1" material="bin2_color"/>
            <!-- <geom name="bin2_side3" type="box" size="0.01 0.15 0.1" pos="0.15 0 0.1" material="bin2_color"/> -->
            <geom name="bin2_side4" type="box" size="0.01 0.15 0.1" pos="-0.15 0 0.1" material="bin2_color"/>
        </body>

        <!-- Cubes -->
        <body name="cube1" pos="0.6 0.4 0.6">
            <freejoint/>
            <geom name="cube1_geom" type="box" size="0.02 0.02 0.02" material="cube_color" mass="0.05"/>
        </body>
        <body name="cube2" pos="0.55 0.35 0.6">
            <freejoint/>
            <geom name="cube2_geom" type="box" size="0.02 0.02 0.02" material="cube_color" mass="0.05"/>
        </body>
        <body name="cube3" pos="0.65 0.45 0.6">
            <freejoint/>
            <geom name="cube3_geom" type="box" size="0.02 0.02 0.02" material="cube_color" mass="0.05"/>
        </body>
    </worldbody>

    <!-- Actuators -->
    <actuator>
        <general class="size3" name="shoulder_pan" joint="shoulder_pan_joint" gear="100" ctrlrange="-2.0 2.0"/>
        <general class="size3" name="shoulder_lift" joint="shoulder_lift_joint" gear="100" ctrlrange="-2.0 2.0"/>
        <general class="size3_limited" name="elbow" joint="elbow_joint" gear="100" ctrlrange="-2.0 2.0"/>
        <general class="size1" name="wrist_1" joint="wrist_1_joint" gear="100" ctrlrange="-2.0 2.0"/>
        <general class="size1" name="wrist_2" joint="wrist_2_joint" gear="100" ctrlrange="-2.0 2.0"/>
        <general class="size1" name="wrist_3" joint="wrist_3_joint" gear="100" ctrlrange="-2.0 2.0"/>
    </actuator>

    <!-- Sensors -->
    <sensor>
        <framepos objtype="site" objname="attachment_site"/>
        <touch name="eef_touch" site="attachment_site"/>
    </sensor>
</mujoco>